Workbook
Name A: PROSES!$Q$27
Name ac: PROSES!$T$81
Name am: PROSES!$T$39
Name Azc: PROSES!$T$95
Name Azm: PROSES!$T$55
Name B: PROSES!$T$77
Name BT: PROSES!$K$10
Name D: PROSES!$S$27
Name dc: PROSES!$T$79
Name Dip: PROSES!$T$49
Name dm: PROSES!$T$37
Name e: PROSES!$T$48
Name GC: PROSES!$T$93
Name GM: PROSES!$T$51
Name hc: PROSES!$T$94
Name hm: PROSES!$T$50
Name Hp: PROSES!$T$91
Name LMT: PROSES!$T$53
Name LT: PROSES!$K$9
Name m: PROSES!$O$27
Name MARKAS: #REF!
Name mh: PROSES!$T$107
Name Mo: PROSES!$T$69
Name N: PROSES!$R$27
Name O: PROSES!$T$27
Name P: PROSES!$T$99
Name PI: PROSES!$N$3
Name Ref: PROSES!$T$98
Name S: PROSES!$N$27
Name sd: PROSES!$T$47
Name sdc: PROSES!$T$92
Name ST: PROSES!$U$27
Name TDL: 'TA''DIL'!$B$5:$AF$365
Name TS: PROSES!$T$35
Name TT: PROSES!$J$9
Name TZ: PROSES!$J$10
Name WQ: PROSES!$P$27
Name Y: PROSES!$T$108
Name z: PROSES!$T$97

Sheet MENU
B3: BELAJAR HISAB AWAL BULAN
B4: METODE "ADDURRUL ANIQ"
B5: Markaz | D5: PONPES RIYADUSSALAM
B6: Lintang Tempat | D6: LS | E6: 7 | F6: 31 | G6: 24 | I6: =IF(D6="LU",E6+F6/60+G6/3600,-(E6+F6/60+G6/3600)) -> -7.5233333
B7: Bujur Tempat | D7: BT | E7: 108 | F7: 16 | G7: 7 | I7: =IF(D7="BT",E7+F7/60+G7/3600,-(E7+F7/60+G7/3600)) -> 108.26861
B8: Tinggi Tempat | D8: 10
B9: Zona Waktu | D9: 7
B10: BULAN | D10: 9
B11: TAHUN | D11: 1447
B12: Plus Hari | D12: 0
B13: =PROSES!X5 -> Lintang tempat : 07° 31' 24" LS Bujur tempat : 108° 16' 07" BT Tinggi tempat : 10 Mtr. Time Zone : 7
B14: =IF(PROSES!J22=0,1," ") -> 1 | C14: =IF(PROSES!J22=0,"Ijtima' akhir bulan","Data Pada hari berikutnya") -> Ijtima' akhir bulan | D14: =IF(PROSES!J22=0,PROSES!N113," ") -> SYA'BAN 1447 H.
B15: =IF(PROSES!J22=0,2,1) -> 2 | C15: Hari / Tanggal | D15: =PROSES!N114 -> SELASA KLIWON 17 FEBRUARI 2026 M.
B16: =IF(PROSES!J22=0,"3"," ") -> 3 | C16: =IF(PROSES!J22=0,"Jam Ijtima'"," ") -> Jam Ijtima' | D16: =IF(PROSES!J22=0,PROSES!N115," ") -> 19:02:01 WIB
B17: =IF(PROSES!J22=0,"4","2") -> 4 | C17: Matahari terbenam | D17: =PROSES!N116 -> 18:11:08 WIB
B18: =IF(PROSES!J22=0,"5","3") -> 5 | C18: Hilal terbenam | D18: =PROSES!N117 -> 18:07:48 WIB
B19: =IF(PROSES!J22=0,"6","4") -> 6 | C19: Ketinggian Hilal Hakiki | D19: =PROSES!N118 -> - 00° 50' 08"
B20: =IF(PROSES!J22=0,"7","5") -> 7 | C20: Ketinggian Hilal Mar'i | D20: =PROSES!N119 -> - 01° 47' 07"
B21: =IF(PROSES!J22=0,"8","6") -> 8 | C21: Elongasi Hilal | D21: =PROSES!N120 -> 01° 08' 20"
B22: =IF(PROSES!J22=0,"9","7") -> 9 | C22: Umur Hilal | D22: =PROSES!N121
B23: =IF(PROSES!J22=0,"10","8") -> 10 | C23: Lamanya Hilal di atas ufuq | D23: =PROSES!N122 -> MASIH DI BAWAH UFUQ
B24: =IF(PROSES!J22=0,"11","9") -> 11 | C24: Azimut Matahari | D24: =PROSES!N123 -> 257° 52' 41"
B25: =IF(PROSES!J22=0,"12","10") -> 12 | C25: Azimut Hilal | D25: =PROSES!N124 -> 256° 44' 34"
B26: =IF(PROSES!J22=0,"13","11") -> 13 | C26: Lebar cahaya Hilal | D26: =PROSES!N125 -> 0.00012776736
B27: =IF(PROSES!J22=0,"14","12") -> 14 | C27: Jarak & Letak Hilal dari Matahari | D27: =PROSES!N126&" "&"( "&PROSES!N129&" )" -> - 01° 08' 08 ( di selatan matahari )
B28: =IF(PROSES!J22=0,"15","13") -> 15 | C28: Keadaan Hilal | D28: =PROSES!N127 -> miring ke selatan
B29: =IF(PROSES!J22=0,"16","14") -> 16 | C29: Posisi Hilal | D29: =PROSES!N128 -> di selatan katulistiwa
B30: =IF(PROSES!J22=0,"17","15") -> 17 | C30: Letak Matahari terbenam | D30: =PROSES!N130 -> di selatan titik barat
B31: =IF(PROSES!J22=0,"18"," ") -> 18 | C31: =IF(PROSES!J22=0,"TGL 1 "&PROSES!F40&" "&PROSES!F42&" "&"H."," ") -> TGL 1 RAMADHAN 1447 H. | D31: =IF(PROSES!J22=0,PROSES!N131," ") -> KAMIS PAHING 19 FEBRUARI 2026 M.

Sheet PROSES
I1: ="AWAL"&" "&F40&" "&J3&" "&"H." -> AWAL RAMADHAN 1447 H.
B2: AKHIR | C2: =IF(F39<2,F39+12-1,F39-1) -> 8 | E2: TAHUN | F2: =IF(F39<2,F42-1,F42) -> 1447
B3: BULAN | C3: =VLOOKUP(C2,B50:C61,2) -> SYA'BAN | I3: TAHUN | J3: =F2 -> 1447 | K3: =MENU!D11 -> 1447 | N3: =PI()/180 -> 0.017453293 | R3: =113+15/60 -> 113.25 | S3: MATAHARI TERBENAM | W3: =MENU!D6 -> LS | X3: =TEXT(ABS(K9/24),"[hh]° mm' ss")&"""" -> 07° 31' 24"
I4: BULAN | J4: =C2 -> 8 | O4: TAHUN HIJRIAH | Q4: Khosotuha | S4: m | T4: =Q10 -> 43.2954 | W4: =MENU!D7 -> BT | X4: =IF(K10<0,"- ", )&TEXT(ABS(K10/24),"[hh]° mm' ss")&"""" -> 108° 16' 07"
B5: ="AKHIR BULAN "&C3&" "&F2&" "&"H." -> AKHIR BULAN SYA'BAN 1447 H. | I5: MARKAS | J5: =MENU!D5 -> PONPES RIYADUSSALAM | Q5: (m) | S5: sd | T5: =0.267/(1-0.017*COS(T4*PI)) -> 0.270345 | X5: ="Lintang tempat : "&X3&" "&W3&" "&"Bujur tempat : "&X4&" "&W4&" "&"Tinggi tempat : "&J9&" "&"Mtr. "&"Time Zone : "&J10 -> Lintang tempat : 07° 31' 24" LS Bujur tempat : 108° 16' 07" BT Tinggi tempat : 10 Mtr. Time Zone : 7
B6: TAHUN HIJRIAH | D6: AL - ALAMAH | E6: HISSOTUL 'ARDI | F6: AL - KHOSSOH | G6: AL - MARKAS | O6: Majmu'ah | P6: =30*INT(J3/30) -> 1440 | Q6: =VLOOKUP(P6,HAROKAT!H6:M71,6) -> 246.405 | S6: Dip | T6: =1.76/60*SQRT(J9) -> 0.092760145
D7: (A) | E7: (F) | F7: (M') | G7: (M) | I7: LINTANG | J7: =MENU!E6 -> 7 | K7: =MENU!F6 -> 31 | L7: =MENU!G6 -> 24 | O7: Mabsuthoh | P7: =J3-P6 -> 7 | Q7: =VLOOKUP(P7,HAROKAT!H77:M106,6) -> 284.2887 | S7: h | T7: =-(T5+34.5/60+T6) -> -0.93810514
B8: MAJMU'AH | C8: =30*INT(F2/30) -> 1440 | D8: =VLOOKUP(C8,HAROKAT!B6:F71,2) -> 2458371.7 | E8: =VLOOKUP(C8,HAROKAT!B6:F71,3) -> 45.5986 | F8: =VLOOKUP(C8,HAROKAT!B6:F71,4) -> 45.2696 | G8: =VLOOKUP(C8,HAROKAT!B6:F71,5) -> 245.8869 | I8: BUJUR | J8: =MENU!E7 -> 108 | K8: =MENU!F7 -> 16 | L8: =MENU!G7 -> 7 | O8: Bulan | P8: =J4 -> 8 | Q8: =VLOOKUP(P8,HAROKAT!H112:M123,6) -> 204.0193 | S8: Deklinasi | T8: =INDEX(HAROKAT!Y6:AJ36,E38,F26) -> -12.091697
B9: MABSUTHOH | C9: =F2-C8 -> 7 | D9: =IF(C9=0,C9,VLOOKUP(C9,HAROKAT!B77:F106,2)) -> 2480.5694 | E9: =IF(C9=0,C9,VLOOKUP(C9,HAROKAT!B77:F106,3)) -> 56.3225 | F9: =IF(C9=0,C9,VLOOKUP(C9,HAROKAT!B77:F106,4)) -> 8.6211 | G9: =IF(C9=0,C9,VLOOKUP(C9,HAROKAT!B77:F106,5)) -> 284.8499 | I9: Tinggi Tempat | J9: =MENU!D8 -> 10 | K9: =MENU!I6 -> -7.5233333 | O9: Hari | P9: =F48 -> 29 | Q9: =VLOOKUP(P9,HAROKAT!H129:M159,6) -> 28.5824 | S9: EQ TIME | T9: =INDEX(HAROKAT!Y40:AJ70,E38,F26) -> -0.23333056
B10: BULAN | C10: =C2 -> 8 | D10: =VLOOKUP(C10,HAROKAT!B112:F123,2) -> 236.2447 | E10: =VLOOKUP(C10,HAROKAT!B112:F123,3) -> 245.3641 | F10: =VLOOKUP(C10,HAROKAT!B112:F123,4) -> 206.5353 | G10: =VLOOKUP(C10,HAROKAT!B112:F123,5) -> 232.8428 | I10: Time Zone | J10: =MENU!D9 -> 7 | K10: =MENU!I7 -> 108.26861 | O10: JUMLAH | Q10: =MOD(SUM(Q6:Q9),360) -> 43.2954 | S10: GHRB LMT | T10: =(ACOS(-TAN(LT*PI)*TAN(T8*PI)+SIN(T7*PI)/COS(LT*PI)/COS(T8*PI))/PI)/15+12-T9 -> 18.405971
B11: JUMLAH | D11: =SUM(D8:D10) -> 2461088.5 | E11: =MOD(SUM(E8:E10),360) -> 347.2852 | F11: =MOD(SUM(F8:F10),360) -> 260.426 | G11: =MOD(SUM(G8:G10),360) -> 43.5796 | I11: S.F.T. | J11: =ABS(K11/24) -> 0.013837191 | K11: =(R3-K10)/15 -> 0.33209259 | T11: =T10/24 -> 0.76691547
I13: السنة الهجرية | K13: العلامة | L13: الأيام | N13: وسط الشمس | O13: خاصتها | P13: وسط القمر | Q13: خاصته | R13: حصة العرض | S13: البعد | T13: الميل الكلى | U13: الوقت النجمى
B14: DALIL | C14: HAROKAT | D14: SATAR AWAL | E14: SATAR TSANI | F14: AL - KASRU | G14: TA'DIL | L14: h | M14: p | N14: S | O14: m | P14: M | Q14: A | R14: N | S14: D | T14: O | U14: ST
B15: Dalil 1 (M) | C15: =G11 -> 43.5796 | D15: =VLOOKUP(INT(C15),TDL,2) -> 0.1183 | E15: =VLOOKUP(INT(C15+1),TDL,2) -> 0.1205 | F15: =C15-INT(C15) -> 0.5796 | G15: =D15-(D15-E15)*F15 -> 0.11957512 | I15: MAJMU'AH | J15: =P6 -> 1440 | K15: =VLOOKUP(J15,HAROKAT!H6:S71,2) -> 2458372 | L15: =VLOOKUP(J15,HAROKAT!H6:S71,3) -> 3 | M15: =VLOOKUP(J15,HAROKAT!H6:S71,4) -> 4 | N15: =VLOOKUP(J15,HAROKAT!H6:S71,5) -> 169.6637 | O15: =VLOOKUP(J15,HAROKAT!H6:S71,6) -> 246.405 | P15: =VLOOKUP(J15,HAROKAT!H6:S71,7) -> 176.0183 | Q15: =VLOOKUP(J15,HAROKAT!H6:S71,8) -> 52.0931 | R15: =VLOOKUP(J15,HAROKAT!H6:S71,9) -> 52.499 | S15: =VLOOKUP(J15,HAROKAT!H6:S71,10) -> 6.3547 | T15: =VLOOKUP(J15,HAROKAT!H6:S71,11) -> 23.43686 | U15: =VLOOKUP(J15,HAROKAT!H6:S71,12) -> 236.408
B16: Dalil 2 (2xM) | C16: =MOD(2*G11,360) -> 87.1592 | D16: =VLOOKUP(INT(C16),TDL,3) -> 0.0021 | E16: =VLOOKUP(INT(C16+1),TDL,3) -> 0.0021 | F16: =C16-INT(C16) -> 0.1592 | G16: =D16-(D16-E16)*F16 -> 0.0021 | I16: MABSUTHOH | J16: =P7 -> 7 | K16: =VLOOKUP(J16,HAROKAT!H77:S106,2) -> 2480 | L16: =VLOOKUP(J16,HAROKAT!H77:S106,3) -> 2 | M16: =VLOOKUP(J16,HAROKAT!H77:S106,4) -> 0 | N16: =VLOOKUP(J16,HAROKAT!H77:S106,5) -> 284.4055 | O16: =VLOOKUP(J16,HAROKAT!H77:S106,6) -> 284.2887 | P16: =VLOOKUP(J16,HAROKAT!H77:S106,7) -> 277.4633 | Q16: =VLOOKUP(J16,HAROKAT!H77:S106,8) -> 1.1826 | R16: =VLOOKUP(J16,HAROKAT!H77:S106,9) -> 48.7886 | S16: =VLOOKUP(J16,HAROKAT!H77:S106,10) -> 353.0578 | T16: =VLOOKUP(J16,HAROKAT!H77:S106,11) -> -0.000883 | U16: =VLOOKUP(J16,HAROKAT!H77:S106,12) -> 284.4055
B17: Dalil 3 (M') | C17: =F11 -> 260.426 | D17: =VLOOKUP(INT(C17),TDL,4) -> 0.4006 | E17: =VLOOKUP(INT(C17+1),TDL,4) -> 0.4018 | F17: =C17-INT(C17) -> 0.426 | G17: =D17-(D17-E17)*F17 -> 0.4011112 | I17: BULAN | J17: =P8 -> 8 | K17: =VLOOKUP(J17,HAROKAT!H112:S123,2) -> 207 | L17: =VLOOKUP(J17,HAROKAT!H112:S123,3) -> 4 | M17: =VLOOKUP(J17,HAROKAT!H112:S123,4) -> 2 | N17: =VLOOKUP(J17,HAROKAT!H112:S123,5) -> 204.029 | O17: =VLOOKUP(J17,HAROKAT!H112:S123,6) -> 204.0193 | P17: =VLOOKUP(J17,HAROKAT!H112:S123,7) -> 207.5141 | Q17: =VLOOKUP(J17,HAROKAT!H112:S123,8) -> 184.4535 | R17: =VLOOKUP(J17,HAROKAT!H112:S123,9) -> 218.4755 | S17: =VLOOKUP(J17,HAROKAT!H112:S123,10) -> 3.4851 | T17: =VLOOKUP(J17,HAROKAT!H112:S123,11) -> -7.4e-05 | U17: =VLOOKUP(J17,HAROKAT!H112:S123,12) -> 204.029
B18: Dalil 4 (2xM') | C18: =MOD(2*F11,360) -> 160.852 | D18: =VLOOKUP(INT(C18),TDL,5) -> 0.0055 | E18: =VLOOKUP(INT(C18+1),TDL,5) -> 0.0052 | F18: =C18-INT(C18) -> 0.852 | G18: =D18-(D18-E18)*F18 -> 0.0052444 | I18: HARI | J18: =P9 -> 29 | K18: =VLOOKUP(J18,HAROKAT!H129:S159,2) -> 29 | L18: =VLOOKUP(J18,HAROKAT!H129:S159,3) -> 1 | M18: =VLOOKUP(J18,HAROKAT!H129:S159,4) -> 4 | N18: =VLOOKUP(J18,HAROKAT!H129:S159,5) -> 28.5838 | O18: =VLOOKUP(J18,HAROKAT!H129:S159,6) -> 28.5824 | P18: =VLOOKUP(J18,HAROKAT!H129:S159,7) -> 22.1155 | Q18: =VLOOKUP(J18,HAROKAT!H129:S159,8) -> 18.8848 | R18: =VLOOKUP(J18,HAROKAT!H129:S159,9) -> 23.6512 | S18: =VLOOKUP(J18,HAROKAT!H129:S159,10) -> 353.5317 | T18: =VLOOKUP(J18,HAROKAT!H129:S159,11) -> -1e-05 | U18: =VLOOKUP(J18,HAROKAT!H129:S159,12) -> 28.5838
B19: Dalil 5 (M+M') | C19: =MOD(G11+F11,360) -> 304.0056 | D19: =VLOOKUP(INT(C19),TDL,6) -> 0.0042 | E19: =VLOOKUP(INT(C19+1),TDL,6) -> 0.0042 | F19: =C19-INT(C19) -> 0.0056 | G19: =D19-(D19-E19)*F19 -> 0.0042 | I19: JAM GHRB | J19: =HOUR(T11) -> 18 | N19: =VLOOKUP(J19,HAROKAT!L165:S189,2) -> 0.7392 | O19: =VLOOKUP(J19,HAROKAT!L165:S189,3) -> 0.7392 | P19: =VLOOKUP(J19,HAROKAT!L165:S189,4) -> 9.8823 | Q19: =VLOOKUP(J19,HAROKAT!L165:S189,5) -> 9.7987 | R19: =VLOOKUP(J19,HAROKAT!L165:S189,6) -> 9.922 | S19: =VLOOKUP(J19,HAROKAT!L165:S189,7) -> 9.1431 | U19: =VLOOKUP(J19,HAROKAT!L165:S189,8) -> 270.7392
B20: Dalil 6 (M-M') | C20: =IF(G11-F11<0,G11-F11+360,MOD(G11-F11,360)) -> 143.1536 | D20: =VLOOKUP(INT(C20),TDL,7) -> -0.0045 | E20: =VLOOKUP(INT(C20+1),TDL,7) -> -0.0043 | F20: =C20-INT(C20) -> 0.1536 | G20: =D20-(D20-E20)*F20 -> -0.00446928 | I20: Menit GHRB | J20: =MINUTE(T11) -> 24 | N20: =VLOOKUP(J20,HAROKAT!L195:S255,2) -> 0.0164 | O20: =VLOOKUP(J20,HAROKAT!L195:S255,3) -> 0.0164 | P20: =VLOOKUP(J20,HAROKAT!L195:S255,4) -> 0.2196 | Q20: =VLOOKUP(J20,HAROKAT!L195:S255,5) -> 0.2177 | R20: =VLOOKUP(J20,HAROKAT!L195:S255,6) -> 0.2205 | S20: =VLOOKUP(J20,HAROKAT!L195:S255,7) -> 0.2032 | U20: =VLOOKUP(J20,HAROKAT!L195:S255,8) -> 6.0164
B21: Dalil 7 (2xF) | C21: =MOD(2*E11,360) -> 334.5704 | D21: =VLOOKUP(INT(C21),TDL,8) -> -0.0046 | E21: =VLOOKUP(INT(C21+1),TDL,8) -> -0.0044 | F21: =C21-INT(C21) -> 0.5704 | G21: =D21-(D21-E21)*F21 -> -0.00448592 | I21: Detik GHRB | J21: =SECOND(T11) -> 21 | N21: =VLOOKUP(J21,HAROKAT!L261:S321,2) -> 0.0002 | O21: =VLOOKUP(J21,HAROKAT!L261:S321,3) -> 0.0002 | P21: =VLOOKUP(J21,HAROKAT!L261:S321,4) -> 0.0032 | Q21: =VLOOKUP(J21,HAROKAT!L261:S321,5) -> 0.0032 | R21: =VLOOKUP(J21,HAROKAT!L261:S321,6) -> 0.0032 | S21: =VLOOKUP(J21,HAROKAT!L261:S321,7) -> 0.003 | U21: =VLOOKUP(J21,HAROKAT!L261:S321,8) -> 0.0877
B22: Dalil 8 (2xF-M') | C22: =IF(2*E11-F11<0,2*E11-F11+360,MOD(2*E11-F11,360)) -> 74.1444 | D22: =VLOOKUP(INT(C22),TDL,9) -> 0.001 | E22: =VLOOKUP(INT(C22+1),'TA''DIL'!B$5:J$365,9) -> 0.001 | F22: =C22-INT(C22) -> 0.1444 | G22: =D22-(D22-E22)*F22 -> 0.001 | I22: Tambahan Hari | J22: =MENU!D12 -> 0 | K22: =VLOOKUP(J22,HAROKAT!H129:S159,2) -> 0 | L22: =VLOOKUP(J22,HAROKAT!H129:S159,3) -> 0 | M22: =VLOOKUP(J22,HAROKAT!H129:S159,4) -> 0 | N22: =VLOOKUP(AC22,HAROKAT!H129:S159,5) -> 0 | O22: =VLOOKUP(J22,HAROKAT!H129:S159,6) -> 0 | P22: =VLOOKUP(J22,HAROKAT!H129:S159,7) -> 0 | Q22: =VLOOKUP(J22,HAROKAT!H129:S159,8) -> 0 | R22: =VLOOKUP(J22,HAROKAT!H129:S159,9) -> 0 | S22: =VLOOKUP(J22,HAROKAT!H129:S159,10) -> 0 | T22: =VLOOKUP(J22,HAROKAT!H129:S159,11) -> 0 | U22: =VLOOKUP(J22,HAROKAT!H129:S159,12) -> 0
I23: JUMLAH 1 | K23: =SUM(K15:K18) -> 2461088 | L23: =MOD(SUM(L15:L18),7) -> 3 | M23: =MOD(SUM(M15:M18),5) -> 0 | N23: =MOD(SUM(N15:N22),360) -> 327.4378 | O23: =MOD(SUM(O15:O22),360) -> 44.0512 | P23: =MOD(SUM(P15:P22),360) -> 333.2163 | Q23: =MOD(SUM(Q15:Q22),360) -> 266.6336 | R23: =MOD(SUM(R15:R22),360) -> 353.56 | S23: =MOD(SUM(S15:S22),360) -> 5.7786 | T23: =SUM(T15:T18) -> 23.435893 | U23: =MOD(SUM(U15:U22),360) -> 310.2696 | X23: IF(H42<0,"- ",)&TEXT(ABS(H42/24),"[hh]° mm' ss")
B24: T | C24: T1 + T2 s/d T8 | D24: UT | E24: WD | F24: Koreksi WD | G24: AWAL BULAN | I24: SFT Jam | J24: =HOUR(J11) -> 0 | N24: =VLOOKUP(J24,HAROKAT!L165:S189,2) -> 0 | O24: =VLOOKUP(J24,HAROKAT!L165:S189,3) -> 0 | P24: =VLOOKUP(J24,HAROKAT!L165:S189,4) -> 0 | Q24: =VLOOKUP(J24,HAROKAT!L165:S189,5) -> 0 | R24: =VLOOKUP(J24,HAROKAT!L165:S189,6) -> 0 | S24: =VLOOKUP(J24,HAROKAT!L165:S189,7) -> 0 | U24: =VLOOKUP(J24,HAROKAT!L165:S189,8) -> 0
D25: =SUM(G15:G22) -> 0.52427552 | E25: =IF(D42>24,D26+1,D26+0) -> 2461089.5 | F25: Bulan | G25: =IF(T100<2,E26+2,E26+1) -> 2461091.5 | I25: SFT Menit | J25: =MINUTE(J11) -> 19 | N25: =VLOOKUP(J25,HAROKAT!L195:S255,2) -> 0.013 | O25: =VLOOKUP(J25,HAROKAT!L195:S255,3) -> 0.013 | P25: =VLOOKUP(J25,HAROKAT!L195:S255,4) -> 0.1739 | Q25: =VLOOKUP(J25,HAROKAT!L195:S255,5) -> 0.1724 | R25: =VLOOKUP(J25,HAROKAT!L195:S255,6) -> 0.1746 | S25: =VLOOKUP(J25,HAROKAT!L195:S255,7) -> 0.1609 | U25: =VLOOKUP(J25,HAROKAT!L195:S255,8) -> 4.763
B26: A.M. | C26: A + T +0,5 | D26: =ROUND(D11+D25+0.5,12) -> 2461089.5 | E26: =E25 -> 2461089.5 | F26: =IF(E37>E36,E33+1,E33) -> 2 | G26: =IF(AND(OR(T111>7.9999999999,T100>1.9999999999),J103>2.9999999999),E26+1,E26+2) -> 2461091.5 | I26: SFT Detik | J26: =SECOND(J11) -> 56 | N26: =VLOOKUP(J26,HAROKAT!L261:S321,2) -> 0.0006 | O26: =VLOOKUP(J26,HAROKAT!L261:S321,3) -> 0.0006 | P26: =VLOOKUP(J26,HAROKAT!L261:S321,4) -> 0.0085 | Q26: =VLOOKUP(J26,HAROKAT!L261:S321,5) -> 0.0085 | R26: =VLOOKUP(J26,HAROKAT!L261:S321,6) -> 0.0086 | S26: =VLOOKUP(J26,HAROKAT!L261:S321,7) -> 0.0079 | U26: =VLOOKUP(J26,HAROKAT!L261:S321,8) -> 0.234
B27: Majmu'ah | C27: =INDEX(HAROKAT!U6:U31,MATCH(PROSES!D30,HAROKAT!V6:V31),1) -> 2000 | D27: =INDEX(HAROKAT!$V6:$V31,MATCH(PROSES!D30,HAROKAT!$V6:$V31),1) -> 2451544 | E27: =INDEX(HAROKAT!$V6:$V31,MATCH(PROSES!E30,HAROKAT!$V6:$V31),1) -> 2451544 | F27: =VLOOKUP(F26,B$50:D$61,3) -> FEBRUARI | G27: =INDEX(HAROKAT!$V6:$V31,MATCH(PROSES!G30,HAROKAT!$V6:$V31),1) -> 2451544 | I27: JUMLAH 2 | K27: =K23 -> 2461088 | L27: =L23 -> 3 | M27: =M23 -> 0 | N27: =IF(K11<0,N23-SUM(N24:N26),MOD(SUM(N23:N26),360)) -> 327.4514 | O27: =IF(K11<0,O23-SUM(O24:O26),MOD(SUM(O23:O26),360)) -> 44.0648 | P27: =IF(K11<0,P23-SUM(P24:P26),MOD(SUM(P23:P26),360)) -> 333.3987 | Q27: =IF(K11<0,Q23-SUM(Q24:Q26),MOD(SUM(Q23:Q26),360)) -> 266.8145 | R27: =IF(K11<0,R23-SUM(R24:R26),MOD(SUM(R23:R26),360)) -> 353.7432 | S27: =IF(K11<0,S23-SUM(S24:S26),MOD(SUM(S23:S26),360)) -> 5.9474 | T27: =T23 -> 23.435893 | U27: =IF(K11<0,U23-SUM(U24:U26),MOD(SUM(U23:U26),360)) -> 315.2666
B28: Mabsuthoh | C28: =INDEX(HAROKAT!U76:U175,MATCH(D31,HAROKAT!V76:V175),1) -> 26 | D28: =INDEX(HAROKAT!$V76:$V175,MATCH(D31,HAROKAT!$V76:$V175),1) -> 9496 | E28: =INDEX(HAROKAT!$V76:$V175,MATCH(E31,HAROKAT!$V76:$V175),1) -> 9496 | F28: Tahun | G28: =INDEX(HAROKAT!$V76:$V175,MATCH(G31,HAROKAT!$V76:$V175),1) -> 9496
B29: Tahun | D29: =C27+C28 -> 2026 | E29: =IF(AND(D33=12,D37>D36),D29+1,D29) -> 2026 | F29: =IF(E37>E36,D29+1,D29) -> 2026 | G29: =IF(AND(G33=12,G37>G36),F29+1,F29) -> 2026
B30: A.M. - 1 | C30: Depan koma | D30: =INT(D26)-1 -> 2461088 | E30: =INT(E26)-1 -> 2461088 | G30: =INT(G25)-1 -> 2461090 | I30: D A T A M A T A H A R I
B31: Jumlah Hari | D31: =D30-D27 -> 9544 | E31: =E30-E27 -> 9544 | F31: Koreksi Awal Bulan | G31: =G30-G27 -> 9546 | I31: 1 | J31: BUJUR MATAHARI / THULUSYSYAMSI (S')
B32: Jumlah Hari | D32: =D31-D28 -> 48 | E32: =E31-E28 -> 48 | F32: Tahun | G32: =G31-G28 -> 50 | J32: DALIL | K32: RUMUS | M32: HAROKAT | O32: MADKHUL 1 | P32: MADKHUL 2 | Q32: SATAR 1 | R32: SATAR 2 | S32: AL - KASRU | T32: TA'DIL
B33: Bulan Masehi | D33: =INDEX(HAROKAT!U196:U207,MATCH(PROSES!D32,HAROKAT!V196:V207),1) -> 2 | E33: =IF(D37>D36,D33+1,D33) -> 2 | F33: =IF(AND(G33=12,G37>G36),G29+1,G29) -> 2026 | G33: =INDEX(HAROKAT!$U196:$U207,MATCH(G32,HAROKAT!$V196:$V207),1) -> 2 | J33: DALIL 1 | K33: m | M33: =O27 -> 44.0648 | O33: =INT(M33) -> 44 | P33: =O33+1 -> 45 | Q33: =VLOOKUP(O33,TDL,10) -> 1.33 | R33: =VLOOKUP(P33,TDL,10) -> 1.3538 | S33: =M33-INT(M33) -> 0.0648 | T33: =Q33-(Q33-R33)*S33 -> 1.3315422
D34: =VLOOKUP(D33,B50:D61,3) -> FEBRUARI | E34: =VLOOKUP(E33,$B50:$D61,3) -> FEBRUARI | F34: Bulan | G34: =VLOOKUP(G33,$B50:$D61,3) -> FEBRUARI | J34: DALIL 2 | K34: 2 x m | M34: =MOD(2*O27,360) -> 88.1296 | O34: =INT(M34) -> 88 | P34: =O34+1 -> 89 | Q34: =VLOOKUP(O34,TDL,11) -> 0.02 | R34: =VLOOKUP(P34,TDL,11) -> 0.02 | S34: =M34-INT(M34) -> 0.1296 | T34: =Q34-(Q34-R34)*S34 -> 0.02
B35: Jumlah Hari | D35: =INDEX(HAROKAT!V196:V207,MATCH(D32,HAROKAT!V196:V207),1) -> 31 | E35: =INDEX(HAROKAT!$V196:$V207,MATCH(D32,HAROKAT!$V196:$V207),1) -> 31 | F35: =IF(G37>G36,G33+1,G33) -> 2 | G35: =INDEX(HAROKAT!$V196:$V207,MATCH(G32,HAROKAT!$V196:$V207),1) -> 31 | J35: S' = S + S1 + S2 | R35: =IF(T35<0,"- ", )&TEXT(ABS(T35/24),"[hh]° mm' ss.00")&"""" -> 328° 48' 10.59" | T35: =S+T33+T34 -> 328.80294
B36: Hari Bulan | D36: =IF(MOD(D29,4)=0,VLOOKUP($D33,$B50:F61,4),VLOOKUP(D33,$B50:$F61,5)) -> 28 | E36: =IF(MOD(E29,4)=0,VLOOKUP($D33,$B50:G61,4),VLOOKUP(E33,$B50:$F61,5)) -> 28 | F36: =VLOOKUP(F35,B$50:D$61,3) -> FEBRUARI | G36: =IF(MOD(F29,4)=0,VLOOKUP($D33,$B50:I61,4),VLOOKUP(G33,$B50:$F61,5)) -> 28
D37: =D32-D35 -> 17 | E37: =E32-E35 -> 17 | F37: HIJRIAH | G37: =G32-G35 -> 19 | I37: 2 | J37: DEKLINASI MATAHARI / MAILUSYSYAMSI (dm) | R37: =IF(T37<0,"- ", )&TEXT(ABS(T37/24),"[hh]° mm' ss.00")&"""" -> - 11° 53' 19.84" | T37: =ASIN(SIN(TS*PI)*SIN(O*PI))/PI -> -11.888844
B38: Tanggal Masehi | D38: =IF(D37>D36,D37-D36,D37) -> 17 | E38: =IF(E37>E36,E37-E36,E37) -> 17 | F38: Bulan | G38: =IF(G37>G36,G37-G36,G37) -> 19 | I38: 3 | J38: ASCENSIOREKTA MATAHARI / MATHLA' MUSTAQIM SYAMSI (am) | R38: =IF(T38<0,"- ", )&TEXT(ABS(T38/24),"[hh]° mm' ss.00")&"""" -> - 29° 03' 23.07" | T38: =ATAN(TAN(TS*PI)*COS(O*PI))/PI -> -29.056409
B39: Delta T | D39: ='Delta T'!C22 -> 75.154286 | F39: =MENU!D10 -> 9 | R39: =IF(T39<0,"- ", )&TEXT(ABS(T39/24),"[hh]° mm' ss.00")&"""" -> 330° 56' 36.93" | T39: =IF(AND(T35>0,T35<=90),T38,IF(AND(T35>=90,T35<=270),T38+180,T38+360)) -> 330.94359
B40: JAM IJTIMA' | C40: ET | D40: =MOD(D26,1)*24 -> 12.054612 | E40: =D40/24 -> 0.50227552 | F40: =VLOOKUP(F39,B50:C61,2) -> RAMADHAN | G40: Zona Waktu
C41: UT | D41: =D40-(D39/3600) -> 12.033736 | E41: =D41/24 -> 0.50140568 | F41: Tahun | G41: =IF(TZ*15=105,"WIB",IF(TZ*15=120,"WITA",IF(TZ*15=135,"WIT","WD"))) -> WIB | I41: 4 | J41: JARAK BUMI - MATAHARI / AL - BU'DU BAINA 'ARDI WA SYAMSI (R)
...

Sheet Delta T
B2: TGL | C2: =PROSES!D38 -> 17
B3: BLN | C3: =PROSES!D33 -> 2
B4: THN | C4: =PROSES!D29 -> 2026
B6: Th | C6: =C4+(C3-1)/12+C2/365 -> 2026.1299
B7: Sbelum -500 | C7: =IF(C4<=-500,-20+32*(C6/100-18.2)*(C6/100-18.2),0) -> 0
B8: -500 s/d 500 | C8: =IF(AND(C4>-500,C4<=501),10583.6-1014.41*(C6/100)+33.78311*(C6/100)*(C6/100)-5.952053*(C6/100)*(C6/100)*(C6/100)-0.1798452*(C6/100)*(C6/100)*(C6/100)*(C6/100)+0.022174192*(C6/100)*(C6/100)*(C6/100)*(C6/100)*(C6/100)+0.0090316521*(C6/100)*(C6/100)*(C6/100)*(C6/100)*(C6/100)*(C6/100),0) -> 0
B9: 500 s/d 1600 | C9: =IF(AND(C$5>500,C$5<=1601),1574.2-556.01*(C6/100-10)+71.23472*(C6/100-10)*(C6/100-10)+0.319781*(C6/100-10)*(C6/100-10)*(C6/100-10)-0.8503463*(C6/100-10)*(C6/100-10)*(C6/100-10)*(C6/100-10)-0.005050998*(C6/100-10)*(C6/100-10)*(C6/100-10)*(C6/100-10)*(C6/100-10)+0.0083572073*(C6/100-10)*(C6/100-10)*(C6/100-10)*(C6/100-10)*(C6/100-10)*(C6/100-10),0) -> 0
B10: 1601 s/d 1700 | C10: =IF(AND(C4>1600,C4<=1701),120-0.9808*(C6-1600)-0.01532*(C6-1600)*(C6-1600)+(C6-1600)*(C6-1600)*(C6-1600)/7129,0) -> 0
B11: 1701 s/d 1800 | C11: =IF(AND(C4>1700,C4<=1801),8.83+0.1603*(C6-1700)-0.0059285*(C6-1700)*(C6-1700)+0.00013336*(C6-1700)*(C6-1700)*(C6-1700)-(C6-1700)*(C6-1700)*(C6-1700)*(C6-1700)/1174000,0) -> 0
B12: 1801 s/d 1860 | C12: =IF(AND(C4>1800,C4<=1861),13.72-0.332447*(C6-1800)+0.0068612*(C6-1800)*(C6-1800)+0.0041116*(C6-1800)*(C6-1800)*(C6-1800)-0.00037436*(C6-1800)*(C6-1800)*(C6-1800)*(C6-1800)+0.0000121272*(C6-1800)*(C6-1800)*(C6-1800)*(C6-1800)*(C6-1800)-0.0000001699*(C6-1800)*(C6-1800)*(C6-1800)*(C6-1800)*(C6-1800)*(C6-1800)+0.000000000875*(C6-1800)*(C6-1800)*(C6-1800)*(C6-1800)*(C6-1800)*(C6-1800)*(C6-1800),0) -> 0
B13: 1861 s/d 1900 | C13: =IF(AND(C4>1860,C4<=1901),7.62+0.5737*(C6-1860)-0.251754*(C6-1860)*(C6-1860)+0.01680668*(C6-1860)*(C6-1860)*(C6-1860)-0.0004473624*(C6-1860)*(C6-1860)*(C6-1860)*(C6-1860)+(C6-1860)*(C6-1860)*(C6-1860)*(C6-1860)*(C6-1860)/233174,0) -> 0
B14: 1901 s/d 1920 | C14: =IF(AND(C4>1900,C4<=1921),-2.79+1.494119*(C6-1900)-0.0598939*(C6-1900)*(C6-1900)+0.0061966*(C6-1900)*(C6-1900)*(C6-1900)-0.000197*(C6-1900)*(C6-1900)*(C6-1900)*(C6-1900),0) -> 0
B15: 1921 s/d 1941 | C15: =IF(AND(C4>1920,C4<=1942),21.2+0.84493*(C6-1920)-0.0761*(C6-1920)*(C6-1920)+0.0020936*(C6-1920)*(C6-1920)*(C6-1920),0) -> 0
B16: 1942 s/d 1961 | C16: =IF(AND(C4>1941,C4<=1962),29.07+0.407*(C6-1950)-(C6-1950)*(C6-1950)/233+(C6-1950)*(C6-1950)*(C6-1950)/2547,0) -> 0
B17: 1962 s/d 1986 | C17: =IF(AND(C4>1961,C4<1987),45.45+1.067*(C6-1975)-(C6-1975)*(C6-1975)/260-(C6-1975)*(C6-1975)*(C6-1975)/718,0) -> 0
B18: 1987 s/d 2005 | C18: =IF(AND(C4>1986,C4<2006),63.86+0.3345*(C6-2000)-0.060374+(C6-2000)*(C6-2000)+0.0017275*(C6-2000)*(C6-2000)+0.000651814*(C6-2000)*(C6-2000)*(C6-2000)*(C6-2000)+0.00002373599*(C6-2000)*(C6-2000)*(C6-2000)*(C6-2000)*(C6-2000),0) -> 0
B19: 2006 s/d 2050 | C19: =IF(AND(C4>2005,C4<2051),62.92+0.32217*(C6-2000)+0.005589*(C6-2000)*(C6-2000),0) -> 75.154286
B20: 2051 s/d 2150 | C20: =IF(AND(C4>2050,C4<2151),-20+32*((C6-1820)/100)*((C6-1820)/100)-0.5628*(2150-C6),0) -> 0
B21: 2151 s/d Seterusnya | C21: =IF(C6>2150,-20+32*((C6-1820)/100)*((C6-1820)/100),0) -> 0
B22: Delta T | C22: =SUM(C7:C21) -> 75.154286

Sheet HAROKAT
B2: جدول الحركات في السنين المجموعة لطلب الإجنماع | H2: جدول الحركات في السنين المجموعة لحركات الشمس والقمر على طول سمفانج
B3: السنة | C3: علامة | D3: حصة العرض | E3: الخاصة | F3: المركز | H3: السنة الهجرية | I3: العلامة | J3: الأيام | L3: وسط الشمس | M3: خاصتها | N3: وسط القمر | O3: خاصته | P3: حصة العرض | Q3: البعد | R3: الميل الكلى | S3: الوقت النجمى | U3: سنة مجموعة ميلادية
B4: الهجرية | C4: A | D4: F | E4: M' | F4: M | J4: h | K4: p | L4: S | M4: m | N4: M | O4: A | P4: N | Q4: D | R4: O | S4: ST | U4: a. Tahun Majmu'Ah | X4: DEKLINASI MATAHARI
B5: 1 | C5: 2 | D5: 3 | E5: 4 | F5: 5 | H5: 1 | I5: 2 | J5: 3 | K5: 4 | L5: 5 | M5: 6 | N5: 7 | O5: 8 | P5: 9 | Q5: 10 | R5: 11 | S5: 12 | U5: سنة | V5: يوليان | X5: TGL | Y5: JANUARI | Z5: PEBRUARI | AA5: MARET | AB5: APRIL | AC5: MEI | AD5: JUNI | AE5: JULI | AF5: AGUSTUS | AG5: SEPTEMBER | AH5: OKTOBER | AI5: NOPEMBER | AJ5: DESEMBER
B6: -180 | C6: 1884297.1 | D6: 330.6204 | E6: 6.7173 | F6: 357.7517 | H6: -180 | I6: 1884298 | J6: 6 | K6: 0 | L6: 255.2142 | M6: 358.8716 | N6: 269.059 | O6: 21.4402 | P6: 345.6697 | Q6: 13.8454 | R6: 23.639325 | S6: 321.9755 | U6: 400 | V6: 1867157 | X6: 1 | Y6: -23.024703 | Z6: -17.186725 | AA6: -7.3244389 | AB6: 4.8051139 | AC6: 15.283111 | AD6: 22.143508 | AE6: 23.056442 | AF6: 17.838389 | AG6: 8.0285167 | AH6: -3.4506917 | AI6: -14.642633 | AJ6: -21.901447
B7: -150 | C7: 1894928.1 | D7: 212.0162 | E7: 300.7155 | F7: 35.6803 | H7: -150 | I7: 1894929 | J7: 4 | K7: 1 | L7: 293.6286 | M7: 36.7896 | N7: 307.3423 | O7: 315.303 | P7: 226.9225 | Q7: 13.7143 | R7: 23.635645 | S7: 0.3891 | U7: 500 | V7: 1903682 | X7: 2 | Y7: -22.9409 | Z7: -16.901314 | AA7: -6.9423944 | AB7: 5.18935 | AC7: 15.580631 | AD7: 22.271611 | AE7: 22.981228 | AF7: 17.581019 | AG7: 7.6634611 | AH7: -3.8377222 | AI7: -14.958239 | AJ7: -22.048728
B8: -120 | C8: 1905559.1 | D8: 93.4118 | E8: 234.7155 | F8: 73.6088 | H8: -120 | I8: 1905560 | J8: 2 | K8: 2 | L8: 332.043 | M8: 74.7076 | N8: 345.6254 | O8: 249.1672 | P8: 108.1747 | Q8: 13.5829 | R8: 23.631962 | S8: 38.8029 | U8: 600 | V8: 1940207 | X8: 3 | Y8: -22.849481 | Z8: -16.610964 | AA8: -6.5587111 | AB8: 5.5720528 | AC8: 15.87385 | AD8: 22.393228 | AE8: 22.899336 | AF8: 17.318892 | AG8: 7.2963417 | AH8: -4.2240139 | AI8: -15.269789 | AJ8: -22.188931
B9: -90 | C9: 1916190.1 | D9: 334.8072 | E9: 168.7173 | F9: 111.5374 | H9: -90 | I9: 1916191 | J9: 0 | K9: 3 | L9: 10.4575 | M9: 112.6255 | N9: 23.9082 | O9: 183.0327 | P9: 349.4264 | Q9: 13.4512 | R9: 23.628275 | S9: 77.2167 | U9: 700 | V9: 1976732 | X9: 4 | Y9: -22.750486 | Z9: -16.315789 | AA9: -6.1735028 | AB9: 5.9531333 | AC9: 16.162681 | AD9: 22.508319 | AE9: 22.810797 | AF9: 17.052083 | AG9: 6.9272528 | AH9: -4.6094722 | AI9: -15.577175 | AJ9: -22.321981
B10: -60 | C10: 1926821.1 | D10: 216.2022 | E10: 102.721 | F10: 149.466 | H10: -60 | I10: 1926822 | J10: 5 | K10: 4 | L10: 48.872 | M10: 150.5434 | N10: 62.1907 | O10: 116.8997 | P10: 230.6775 | Q10: 13.3192 | R10: 23.624584 | S10: 115.6305 | U10: 800 | V10: 2013257 | X10: 5 | Y10: -22.643964 | Z10: -16.015903 | AA10: -5.786875 | AB10: 6.3324917 | AC10: 16.447039 | AD10: 22.616842 | AE10: 22.71565 | AF10: 16.780683 | AG10: 6.5562778 | AH10: -4.9939917 | AI10: -15.880278 | AJ10: -22.447811
B11: -30 | C11: 1937452.1 | D11: 97.597 | E11: 36.7265 | F11: 187.3946 | H11: -30 | I11: 1937453 | J11: 3 | K11: 0 | L11: 87.2866 | M11: 188.4613 | N11: 100.473 | O11: 50.7681 | P11: 111.928 | Q11: 13.1869 | R11: 23.620889 | S11: 154.0445 | U11: 900 | V11: 2049782 | X11: 6 | Y11: -22.529969 | Z11: -15.711419 | AA11: -5.3989389 | AB11: 6.7100333 | AC11: 16.726836 | AD11: 22.718753 | AE11: 22.613931 | AF11: 16.504767 | AG11: 6.1835111 | AH11: -5.3774778 | AI11: -16.178992 | AJ11: -22.566358
B12: 0 | C12: 1948083.1 | D12: 338.9915 | E12: 330.7338 | F12: 225.3232 | H12: 0 | I12: 1948084 | J12: 1 | K12: 1 | L12: 125.7012 | M12: 226.3791 | N12: 138.7551 | O12: 344.6378 | P12: 353.1779 | Q12: 13.0543 | R12: 23.617191 | S12: 192.4585 | U12: 1000 | V12: 2086307 | X12: 7 | Y12: -22.408556 | Z12: -15.402456 | AA12: -5.0098 | AB12: 7.0856611 | AC12: 17.001992 | AD12: 22.814022 | AE12: 22.505681 | AF12: 16.224425 | AG12: 5.8090417 | AH12: -5.759825 | AI12: -16.473197 | AJ12: -22.677553
B13: 30 | C13: 1958714.1 | D13: 220.3857 | E13: 264.7429 | F13: 263.2517 | H13: 30 | I13: 1958715 | J13: 6 | K13: 2 | L13: 164.1159 | M13: 264.2969 | N13: 177.0369 | O13: 278.509 | P13: 234.4273 | Q13: 12.9214 | R13: 23.613489 | S13: 230.8725 | U13: 1100 | V13: 2122832 | X13: 8 | Y13: -22.279781 | Z13: -15.089122 | AA13: -4.6195639 | AB13: 7.4592833 | AC13: 17.272417 | AD13: 22.902611 | AE13: 22.390947 | AF13: 15.939736 | AG13: 5.4329583 | AH13: -6.1409333 | AI13: -16.762789 | AJ13: -22.781342
B14: 60 | C14: 1969345.1 | D14: 101.7797 | E14: 198.7539 | F14: 301.1803 | H14: 60 | I14: 1969346 | J14: 4 | K14: 3 | L14: 202.5306 | M14: 302.2147 | N14: 215.3185 | O14: 212.3816 | P14: 115.6761 | Q14: 12.7883 | R14: 23.609783 | S14: 269.2867 | U14: 1200 | V14: 2159357 | X14: 9 | Y14: -22.143711 | Z14: -14.771539 | AA14: -4.2283389 | AB14: 7.8308028 | AC14: 17.538031 | AD14: 22.984486 | AE14: 22.269772 | AF14: 15.650789 | AG14: 5.0553556 | AH14: -6.5207 | AI14: -17.04765 | AJ14: -22.877667
B15: 90 | C15: 1979976.1 | D15: 343.1734 | E15: 132.7667 | F15: 339.1089 | H15: 90 | I15: 1979977 | J15: 2 | K15: 4 | L15: 240.9454 | M15: 340.1325 | N15: 253.5999 | O15: 146.2557 | P15: 356.9243 | Q15: 12.6548 | R15: 23.606074 | S15: 307.7009 | U15: 1300 | V15: 2195882 | X15: 10 | Y15: -22.000411 | Z15: -14.449819 | AA15: -3.8362306 | AB15: 8.2001278 | AC15: 17.798753 | AD15: 23.059622 | AE15: 22.142206 | AF15: 15.357667 | AG15: 4.6763194 | AH15: -6.899025 | AI15: -17.327669 | AJ15: -22.966475
B16: 120 | C16: 1990607.2 | D16: 224.5668 | E16: 66.7813 | F16: 17.0374 | H16: 120 | I16: 1990608 | J16: 0 | K16: 0 | L16: 279.3602 | M16: 18.0502 | N16: 291.881 | O16: 80.1311 | P16: 238.172 | Q16: 12.5211 | R16: 23.602362 | S16: 346.1151 | U16: 1400 | V16: 2232407 | X16: 11 | Y16: -21.84995 | Z16: -14.124078 | AA16: -3.4433444 | AB16: 8.5671583 | AC16: 18.054497 | AD16: 23.127992 | AE16: 22.008297 | AF16: 15.060453 | AG16: 4.2959444 | AH16: -7.2758056 | AI16: -17.602739 | AJ16: -23.047714
B17: 150 | C17: 2001238.2 | D17: 105.9599 | E17: 0.7978 | F17: 54.966 | H17: 150 | I17: 2001239 | J17: 5 | K17: 1 | L17: 317.7751 | M17: 55.968 | N17: 330.1619 | O17: 14.008 | P17: 119.4191 | Q17: 12.3871 | R17: 23.598647 | S17: 24.5295 | U17: 1500 | V17: 2268932 | X17: 12 | Y17: -21.692397 | Z17: -13.794433 | AA17: -3.0497861 | AB17: 8.9318028 | AC17: 18.305186 | AD17: 23.189567 | AE17: 21.868097 | AF17: 14.759239 | AG17: 3.9143194 | AH17: -7.6509361 | AI17: -17.872744 | AJ17: -23.121344
... B31: 570 | C31: 2150072.3 | D31: 245.4344 | E31: 157.2226 | F31: 225.9655 | H31: 570 | I31: 2150073 | J31: 5 | K31: 0 | L31: 135.5889 | M31: 226.8132 | N31: 146.0692 | O31: 168.4347 | P31: 256.8177 | Q31: 10.4805 | R31: 23.546331 | S31: 202.337 | U31: 2900 | V31: 2780262 | X31: 26 | Y31: -18.789233 | Z31: -8.8340694 | AA31: 2.4730306 | AB31: 13.734067 | AC31: 21.241456 | AD31: 23.331281 | AE31: 19.278169 | AF31: 10.170519 | AG31: -1.5079278 | AH31: -12.670153 | AI31: -21.061606 | AJ31: -23.336967
B32: 600 | C32: 2160703.3 | D32: 126.8233 | E32: 91.2669 | F32: 263.894 | H32: 600 | I32: 2160704 | J32: 3 | K32: 1 | L32: 174.0046 | M32: 264.7306 | N32: 184.3465 | O32: 102.3332 | P32: 138.0562 | Q32: 10.3422 | R32: 23.542576 | S32: 240.7523 | X32: 27 | Y32: -18.535789 | Z32: -8.4596667 | AA32: 2.8644 | AB32: 14.051772 | AC32: 21.407419 | AD32: 23.289894 | AE32: 19.051033 | AF32: 9.8197194 | AG32: -1.8971722 | AH32: -13.007722 | AI32: -21.243092 | AJ32: -23.293689
B33: 630 | C33: 2171334.3 | D33: 8.212 | E33: 25.3131 | F33: 301.8225 | H33: 630 | I33: 2171335 | J33: 1 | K33: 2 | L33: 212.4203 | M33: 302.6478 | N33: 222.6236 | O33: 36.2332 | P33: 19.2941 | Q33: 10.2036 | R33: 23.538818 | S33: 279.1677 | X33: 28 | Y33: -18.276742 | Z33: -8.0831861 | AA33: 3.254825 | AB33: 14.365619 | AC33: 21.567211 | AD33: 23.241694 | AE33: 18.818661 | AF33: 9.4663194 | AG33: -2.2861667 | AH33: -13.341914 | AI33: -21.417906 | AJ33: -23.242619
B34: 660 | C34: 2181965.4 | D34: 249.6003 | E34: 319.3612 | F34: 339.751 | H34: 660 | I34: 2181966 | J34: 6 | K34: 3 | L34: 250.836 | M34: 340.5651 | N34: 260.9005 | O34: 330.1346 | P34: 260.5314 | Q34: 10.0647 | R34: 23.535059 | S34: 317.5832 | X34: 29 | Y34: -18.012206 | Z34: -7.7047417 | AA34: 3.6442083 | AB34: 14.675517 | AC34: 21.720767 | AD34: 23.186703 | AE34: 18.581133 | AF34: 9.1104111 | AG34: -2.6748167 | AH34: -13.672614 | AI34: -21.585958 | AJ34: -23.183786
B35: 690 | C35: 2192596.4 | D35: 130.9884 | E35: 253.4111 | F35: 17.6795 | H35: 690 | I35: 2192597 | J35: 4 | K35: 4 | L35: 289.2518 | M35: 18.4824 | N35: 299.1771 | O35: 264.0374 | P35: 141.7681 | Q35: 9.9255 | R35: 23.531298 | S35: 355.9987 | X35: 30 | Y35: -17.742281 | AA35: 4.0324472 | AB35: 14.981378 | AC35: 21.868036 | AD35: 23.124942 | AE35: 18.338528 | AF35: 8.7520806 | AG35: -3.063025 | AH35: -13.999706 | AI35: -21.747167 | AJ35: -23.117217
B36: 720 | C36: 2203227.4 | D36: 12.3762 | E36: 187.463 | F36: 55.608 | H36: 720 | I36: 2203228 | J36: 2 | K36: 0 | L36: 327.6677 | M36: 56.3996 | N36: 337.4535 | O36: 197.9418 | P36: 23.0042 | Q36: 9.786 | R36: 23.527535 | S36: 34.4143 | X36: 31 | Y36: -17.467083 | AA36: 4.41945 | AC36: 22.008967 | AE36: 18.090919 | AF36: 8.3914194 | AH36: -14.323083 | AJ36: -23.042939
B37: 750 | C37: 2213858.4 | D37: 253.7637 | E37: 121.5167 | F37: 93.5365 | H37: 750 | I37: 2213859 | J37: 0 | K37: 1 | L37: 6.0836 | M37: 94.3168 | N37: 15.7297 | O37: 131.8476 | P37: 264.2398 | Q37: 9.6463 | R37: 23.52377 | S37: 72.8299
B38: 780 | C38: 2224489.4 | D38: 135.1509 | E38: 55.5723 | F38: 131.465 | H38: 780 | I38: 2224490 | J38: 5 | K38: 2 | L38: 44.4996 | M38: 132.2339 | N38: 54.0056 | O38: 65.7549 | P38: 145.4748 | Q38: 9.5063 | R38: 23.520003 | S38: 111.2456 | X38: EQUATION OF TIME MATAHARI
B39: 810 | C39: 2235120.4 | D39: 16.5379 | E39: 349.6298 | F39: 169.3935 | H39: 810 | I39: 2235121 | J39: 3 | K39: 3 | L39: 82.9156 | M39: 170.1511 | N39: 92.2813 | O39: 359.6637 | P39: 26.7092 | Q39: 9.3659 | R39: 23.516235 | S39: 149.6614 | X39: TGL | Y39: JANUARI | Z39: PEBRUARI | AA39: MARET | AB39: APRIL | AC39: MEI | AD39: JUNI | AE39: JULI | AF39: AGUSTUS | AG39: SEPTEMBER | AH39: OKTOBER | AI39: NOPEMBER | AJ39: DESEMBER
B40: 840 | C40: 2245751.4 | D40: 257.9245 | E40: 283.6892 | F40: 207.3219 | H40: 840 | I40: 2245752 | J40: 1 | K40: 4 | L40: 121.3316 | M40: 208.0682 | N40: 130.5568 | O40: 293.574 | P40: 267.9431 | Q40: 9.2254 | R40: 23.512465 | S40: 188.0772 | X40: 1 | Y40: -0.054577778 | Z40: -0.22446667 | AA40: -0.20363333 | AB40: -0.061902778 | AC40: 0.049794444 | AD40: 0.035652778 | AE40: -0.065147222 | AF40: -0.10441944 | AG40: 0.0030055556 | AH40: 0.17536389 | AI40: 0.27439722 | AJ40: 0.18088611
B41: 870 | C41: 2256382.4 | D41: 139.3109 | E41: 217.7504 | F41: 245.2504 | H41: 870 | I41: 2256383 | J41: 6 | K41: 0 | L41: 159.7478 | M41: 245.9853 | N41: 168.8321 | O41: 227.4857 | P41: 149.1763 | Q41: 9.0845 | R41: 23.508694 | S41: 226.4932 | X41: 2 | Y41: -0.062430556 | Z41: -0.22667778 | AA41: -0.20025 | AB41: -0.056983333 | AC41: 0.051638889 | AD41: 0.032991667 | AE41: -0.065052778 | AF41: -0.10320833 | AG41: 0.008375 | AH41: 0.18065556 | AI41: 0.27460556 | AJ41: 0.17447778
B42: 900 | C42: 2267013.5 | D42: 20.697 | E42: 151.8136 | F42: 283.1789 | H42: 900 | I42: 2267014 | J42: 4 | K42: 1 | L42: 198.1639 | M42: 283.9023 | N42: 207.1071 | O42: 161.3989 | P42: 30.409 | Q42: 8.9433 | R42: 23.504921 | S42: 264.9091 | X42: 3 | Y42: -0.070188889 | Z42: -0.22865833 | AA42: -0.19673611 | AB42: -0.052105556 | AC42: 0.053327778 | AD42: 0.030227778 | AE42: -0.071333333 | AF42: -0.10182778 | AG42: 0.013822222 | AH42: 0.18585556 | AI42: 0.27458611 | AJ42: 0.16789722
B43: 930 | C43: 2277644.5 | D43: 262.0828 | E43: 85.8787 | F43: 321.1074 | H43: 930 | I43: 2277645 | J43: 2 | K43: 2 | L43: 236.5801 | M43: 321.8194 | N43: 245.3819 | O43: 95.3136 | P43: 271.6411 | Q43: 8.8019 | R43: 23.501147 | S43: 303.3252 | X43: 4 | Y43: -0.077847222 | Z43: -0.23041667 | AA43: -0.19309722 | AB43: -0.047269444 | AC43: 0.054866667 | AD43: 0.027366667 | AE43: -0.0743 | AF43: -0.10028056 | AG43: 0.019338889 | AH43: 0.19096111 | AI43: 0.27433889 | AJ43: 0.16115833
B44: 960 | C44: 2288275.5 | D44: 143.4683 | E44: 19.9457 | F44: 359.0358 | H44: 960 | I44: 2288276 | J44: 0 | K44: 3 | L44: 274.9964 | M44: 359.7364 | N44: 283.6564 | O44: 29.2298 | P44: 152.8727 | Q44: 8.6602 | R44: 23.497372 | S44: 341.7413 | X44: 5 | Y44: -0.085391667 | Z44: -0.23194722 | AA44: -0.18933333 | AB44: -0.042486111 | AC44: 0.056247222 | AD44: 0.024413889 | AE44: -0.077175 | AF44: -0.098566667 | AG44: 0.024919444 | AH44: 0.19596667 | AI44: 0.27386389 | AJ44: 0.15426111
B45: 990 | C45: 2298906.5 | D45: 24.8535 | E45: 314.0145 | F45: 36.9643 | H45: 990 | I45: 2298907 | J45: 5 | K45: 4 | L45: 313.4127 | M45: 37.6534 | N45: 321.9307 | O45: 323.1475 | P45: 34.1037 | Q45: 8.5182 | R45: 23.493596 | S45: 20.1575 | X45: 6 | Y45: -0.092819444 | Z45: -0.23325556 | AA45: -0.18545278 | AB45: -0.037755556 | AC45: 0.057472222 | AD45: 0.021375 | AE45: -0.07995 | AF45: -0.096688889 | AG45: 0.030561111 | AH45: 0.20086667 | AI45: 0.27315556 | AJ45: 0.14721389
B46: 1020 | C46: 2309537.5 | D46: 266.2384 | E46: 248.0853 | F46: 74.8928 | H46: 1020 | I46: 2309538 | J46: 3 | K46: 0 | L46: 351.8291 | M46: 75.5703 | N46: 0.2048 | O46: 257.0667 | P46: 275.334 | Q46: 8.3759 | R46: 23.489818 | S46: 58.5737 | X46: 7 | Y46: -0.099877778 | Z46: -0.23433889 | AA46: -0.18146389 | AB46: -0.033083333 | AC46: 0.058541667 | AD46: 0.018252778 | AE46: -0.082619444 | AF46: -0.094644444 | AG46: 0.036255556 | AH46: 0.20565556 | AI46: 0.27221667 | AJ46: 0.140025
B47: 1050 | C47: 2320168.5 | D47: 147.623 | E47: 182.158 | F47: 112.8212 | H47: 1050 | I47: 2320169 | J47: 1 | K47: 1 | L47: 30.2455 | M47: 113.4873 | N47: 38.4787 | O47: 190.9873 | P47: 156.5639 | Q47: 8.2333 | R47: 23.48604 | S47: 96.99 | X47: 8 | Y47: -0.10728889 | Z47: -0.2352 | AA47: -0.17736667 | AB47: -0.028475 | AC47: 0.059452778 | AD47: 0.015055556 | AE47: -0.085183333 | AF47: -0.092436111 | AG47: 0.042002778 | AH47: 0.210325 | AI47: 0.27104167 | AJ47: 0.13270556
B48: 1080 | C48: 2330799.5 | D48: 29.0074 | E48: 116.2326 | F48: 150.7497 | H48: 1080 | I48: 2330800 | J48: 6 | K48: 2 | L48: 68.662 | M48: 151.4042 | N48: 76.7523 | O48: 124.9095 | P48: 37.7931 | Q48: 8.0905 | R48: 23.48226 | S48: 135.4064 | X48: 9 | Y48: -0.11431389 | Z48: -0.23584167 | AA48: -0.17316944 | AB48: -0.023936111 | AC48: 0.060205556 | AD48: 0.011788889 | AE48: -0.087633333 | AF48: -0.090066667 | AG48: 0.047791667 | AH48: 0.214875 | AI48: 0.26963333 | AJ48: 0.12525556
B49: 1110 | C49: 2341430.5 | D49: 270.3914 | E49: 50.3091 | F49: 188.6781 | H49: 1110 | I49: 2341431 | J49: 4 | K49: 3 | L49: 107.0785 | M49: 189.321 | N49: 115.0257 | O49: 58.8332 | P49: 279.0218 | Q49: 7.9474 | R49: 23.47848 | S49: 173.8228 | X49: 10 | Y49: -0.12119167 | Z49: -0.23626389 | AA49: -0.16887778 | AB49: -0.019472222 | AC49: 0.0608 | AD49: 0.0084583333 | AE49: -0.089966667 | AF49: -0.087538889 | AG49: 0.053622222 | AH49: 0.21929444 | AI49: 0.26798889 | AJ49: 0.11769167
B50: 1140 | C50: 2352061.5 | D50: 151.7752 | E50: 344.3875 | F50: 226.6066 | H50: 1140 | I50: 2352062 | J50: 2 | K50: 4 | L50: 145.4951 | M50: 227.2379 | N50: 153.2989 | O50: 352.7583 | P50: 160.2498 | Q50: 7.804 | R50: 23.474699 | S50: 212.2393 | X50: 11 | Y50: -0.12791389 | Z50: -0.23647222 | AA50: -0.16449722 | AB50: -0.015086111 | AC50: 0.061233333 | AD50: 0.0050666667 | AE50: -0.092175 | AF50: -0.08485 | AG50: 0.059483333 | AH50: 0.22358056 | AI50: 0.26610833 | AJ50: 0.11001389
B51: 1170 | C51: 2362692.6 | D51: 33.1587 | E51: 278.4679 | F51: 264.535 | H51: 1170 | I51: 2362693 | J51: 0 | K51: 0 | L51: 183.9118 | M51: 265.1547 | N51: 191.5719 | O51: 286.685 | P51: 41.4774 | Q51: 7.6603 | R51: 23.470917 | S51: 250.6559 | X51: 12 | Y51: -0.134475 | Z51: -0.23646667 | AA51: -0.16003333 | AB51: -0.010786111 | AC51: 0.061508333 | AD51: 0.001625 | AE51: -0.094258333 | AF51: -0.082008333 | AG51: 0.065375 | AH51: 0.22773056 | AI51: 0.26399167 | AJ51: 0.10223611
... B68: 1680 | C68: 2543419.8 | D68: 176.6572 | E68: 237.9936 | F68: 189.3124 | H68: 1680 | I68: 2543420 | J68: 1 | K68: 2 | L68: 117.0023 | M68: 189.7368 | N68: 122.1776 | O68: 243.6706 | P68: 182.2568 | Q68: 5.1755 | R68: 23.406587 | S68: 183.7476 | X68: 29 | Y68: -0.216475 | Z68: -0.20687778 | AA68: -0.076836111 | AB68: 0.045661111 | AC68: 0.042975 | AD68: -0.058658333 | AE68: -0.10703889 | AF68: -0.012613889 | AG68: 0.16453611 | AH68: 0.27244722 | AI68: 0.19317222 | AJ68: -0.029986111
B69: 1710 | C69: 2554050.8 | D69: 58.0395 | E69: 172.0841 | F69: 227.2406 | H69: 1710 | I69: 2554051 | J69: 6 | K69: 3 | L69: 155.4199 | M69: 227.6531 | N69: 160.4465 | O69: 177.6248 | P69: 63.474 | Q69: 5.0268 | R69: 23.402805 | S69: 222.1654 | X69: 30 | Y69: -0.21936389 | AA69: -0.071833333 | AB69: 0.047802778 | AC69: 0.04065 | AD69: -0.061936111 | AE69: -0.10633333 | AF69: -0.0074944444 | AG69: 0.16998889 | AH69: 0.27331667 | AI69: 0.18711944 | AJ69: -0.021952778
B70: 1740 | C70: 2564681.8 | D70: 299.4218 | E70: 106.1746 | F70: 265.1688 | H70: 1740 | I70: 2564682 | J70: 4 | K70: 4 | L70: 193.8375 | M70: 265.5695 | N70: 198.7152 | O70: 111.5804 | P70: 304.6905 | Q70: 4.8779 | R70: 23.399024 | S70: 260.5832 | X70: 31 | Y70: -0.22203056 | AA70: -0.066852778 | AC70: 0.038205556 | AE70: -0.10546111 | AF70: -0.0022861111 | AH70: 0.27396667 | AJ70: -0.047330556
...

Sheet TA'DIL
B2: Dr | C2: تعديل العلامة للإجتماع | K2: جدول التعديل لطول الشمس | M2: تعديل البعد بين الأرض والشمس | O2: تعديل طول القمر | X2: تعديل عرض القمر | AB2: تعديل البعد بين الأرض والقمر | AF2: نور القمر
C3: T1 | D3: T2 | E3: T3 | F3: T4 | G3: T5 | H3: T6 | I3: T7 | J3: T8 | K3: L1 | L3: L2 | M3: R1 | N3: R2 | O3: M1 | P3: M2 | Q3: M3 | R3: M4 | S3: M5 | T3: M6 | U3: M7 | V3: M8 | W3: M9 | X3: B1 | Y3: B2 | Z3: B3 | AA3: B4 | AB3: r1 | AC3: r2 | AD3: r3 | AE3: r4 | AF3: NQ
B4: 1 | C4: =B4+1 -> 2 | D4: =C4+1 -> 3 | E4: =D4+1 -> 4 | F4: =E4+1 -> 5 | G4: =F4+1 -> 6 | H4: =G4+1 -> 7 | I4: =H4+1 -> 8 | J4: =I4+1 -> 9 | ... AF4: =AE4+1 -> 31
B5: 0 | C5: 0 | D5: 0 | E5: 0 | F5: 0 | G5: 0 | H5: 0 | I5: 0 | J5: 0 | K5: 0 | L5: 0 | M5: 0 | N5: 0 | O5: 0 | P5: 0 | Q5: 0 | R5: 0 | S5: 0 | T5: 0 | U5: 0 | V5: 0 | W5: 0 | X5: 0 | Y5: 0 | Z5: 0 | AA5: 0 | AB5: -20905.355 | AC5: -3699.111 | AD5: -2955.968 | AE5: -569.925 | AF5: 1
B6: 1 | C6: 0.003 | D6: 0 | E6: -0.0071 | F6: 0.0003 | G6: -0.0001 | H6: -0.0001 | I6: 0.0002 | J6: 0 | K6: 0.0334 | L6: 0.0003 | M6: -0.0167 | N6: -0.00014 | O6: 0.1098 | P6: 0.0222 | Q6: 0.0115 | R6: 0.0037 | S6: -0.0032 | T6: -0.002 | U6: 0.001 | V6: 0.001 | W6: 0.0009 | X6: 0.0895 | Y6: 0.0049 | Z6: 0.0048 | AA6: 0.003 | AB6: -20902.171 | AC6: -3698.5476 | AD6: -2955.5178 | AE6: -569.8382 | AF6: 0.9999
B7: =B6+1 -> 2 | C7: 0.0061 | D7: 0.0001 | E7: -0.0142 | F7: 0.0006 | G7: -0.0002 | H7: -0.0003 | I7: 0.0004 | J7: 0 | K7: 0.0668 | L7: 0.0007 | M7: -0.01669 | N7: -0.00014 | O7: 0.2195 | P7: 0.0445 | Q7: 0.023 | R7: 0.0075 | S7: -0.0065 | T7: -0.004 | U7: 0.0021 | V7: 0.002 | W7: 0.0019 | X7: 0.179 | Y7: 0.0098 | Z7: 0.0097 | AA7: 0.006 | AB7: -20892.62 | AC7: -3696.8576 | AD7: -2954.1673 | AE7: -569.5778 | AF7: 0.9997
B8: =B7+1 -> 3 | C8: 0.0091 | D8: 0.0001 | E8: -0.0213 | F8: 0.0008 | G8: -0.0003 | H8: -0.0004 | I8: 0.0005 | J8: 0.0001 | K8: 0.1002 | L8: 0.001 | M8: -0.01668 | N8: -0.00014 | O8: 0.3291 | P8: 0.0667 | Q8: 0.0345 | R8: 0.0112 | S8: -0.0097 | T8: -0.006 | U8: 0.0031 | V8: 0.003 | W8: 0.0028 | X8: 0.2684 | Y8: 0.0147 | Z8: 0.0145 | AA8: 0.0091 | AB8: -20876.705 | AC8: -3694.0415 | AD8: -2951.9169 | AE8: -569.1439 | AF8: 0.9993
B9: =B8+1 -> 4 | C9: 0.0121 | D9: 0.0001 | E9: -0.0284 | F9: 0.0011 | G9: -0.0004 | H9: -0.0005 | I9: 0.0007 | J9: 0.0001 | K9: 0.1336 | L9: 0.0014 | M9: -0.01666 | N9: -0.00014 | O9: 0.4387 | P9: 0.0889 | Q9: 0.0459 | R9: 0.0149 | S9: -0.0129 | T9: -0.008 | U9: 0.0041 | V9: 0.004 | W9: 0.0037 | X9: 0.3577 | Y9: 0.0196 | Z9: 0.0194 | AA9: 0.0121 | AB9: -20854.431 | AC9: -3690.1002 | AD9: -2948.7674 | AE9: -568.5367 | AF9: 0.9988
B10: =B9+1 -> 5 | C10: 0.0151 | D10: 0.0002 | E10: -0.0355 | F10: 0.0014 | G10: -0.0004 | H10: -0.0006 | I10: 0.0009 | J10: 0.0001 | K10: 0.1669 | L10: 0.0017 | M10: -0.01664 | N10: -0.00014 | O10: 0.5481 | P10: 0.111 | Q10: 0.0574 | R10: 0.0186 | S10: -0.0161 | T10: -0.01 | U10: 0.0051 | V10: 0.005 | W10: 0.0046 | X10: 0.447 | Y10: 0.0245 | Z10: 0.0242 | AA10: 0.0151 | AB10: -20825.804 | AC10: -3685.0348 | AD10: -2944.7196 | AE10: -567.7563 | AF10: 0.9981
B11: =B10+1 -> 6 | C11: 0.0181 | D11: 0.0002 | E11: -0.0425 | F11: 0.0017 | G11: -0.0005 | H11: -0.0008 | I11: 0.0011 | J11: 0.0001 | K11: 0.2001 | L11: 0.0021 | M11: -0.01661 | N11: -0.00014 | O11: 0.6574 | P11: 0.1332 | Q11: 0.0688 | R11: 0.0223 | S11: -0.0193 | T11: -0.012 | U11: 0.0061 | V11: 0.006 | W11: 0.0056 | X11: 0.536 | Y11: 0.0293 | Z11: 0.029 | AA11: 0.0181 | AB11: -20790.833 | AC11: -3678.8469 | AD11: -2939.7749 | AE11: -566.8029 | AF11: 0.9973
B12: =B11+1 -> 7 | C12: 0.0211 | D12: 0.0003 | E12: -0.0496 | F12: 0.002 | G12: -0.0006 | H12: -0.0009 | I12: 0.0013 | J12: 0.0001 | K12: 0.2333 | L12: 0.0024 | M12: -0.01658 | N12: -0.00014 | O12: 0.7664 | P12: 0.1553 | Q12: 0.0802 | R12: 0.026 | S12: -0.0226 | T12: -0.0139 | U12: 0.0072 | V12: 0.007 | W12: 0.0065 | X12: 0.625 | Y12: 0.0342 | Z12: 0.0338 | AA12: 0.0211 | AB12: -20749.53 | AC12: -3671.5384 | AD12: -2933.9347 | AE12: -565.6769 | AF12: 0.9963
B13: =B12+1 -> 8 | C13: 0.0241 | D13: 0.0003 | E13: -0.0566 | F13: 0.0022 | G13: -0.0007 | H13: -0.001 | I13: 0.0014 | J13: 0.0001 | K13: 0.2665 | L13: 0.0028 | M13: -0.01654 | N13: -0.00014 | O13: 0.8752 | P13: 0.1773 | Q13: 0.0916 | R13: 0.0297 | S13: -0.0258 | T13: -0.0159 | U13: 0.0082 | V13: 0.0079 | W13: 0.0074 | X13: 0.7137 | Y13: 0.0391 | Z13: 0.0386 | AA13: 0.0241 | AB13: -20701.906 | AC13: -3663.1115 | AD13: -2927.2007 | AE13: -564.3785 | AF13: 0.9951
B14: =B13+1 -> 9 | C14: 0.0271 | D14: 0.0003 | E14: -0.0636 | F14: 0.0025 | G14: -0.0008 | H14: -0.0012 | I14: 0.0016 | J14: 0.0002 | K14: 0.2995 | L14: 0.0031 | M14: -0.01649 | N14: -0.00014 | O14: 0.9838 | P14: 0.1993 | Q14: 0.103 | R14: 0.0334 | S14: -0.029 | T14: -0.0179 | U14: 0.0092 | V14: 0.0089 | W14: 0.0083 | X14: 0.8022 | Y14: 0.0439 | Z14: 0.0434 | AA14: 0.0271 | AB14: -20647.975 | AC14: -3653.5688 | AD14: -2919.5751 | AE14: -562.9083 | AF14: 0.9938
B15: =B14+1 -> 10 | C15: 0.0301 | D15: 0.0004 | E15: -0.0706 | F15: 0.0028 | G15: -0.0009 | H15: -0.0013 | I15: 0.0018 | J15: 0.0002 | K15: 0.3325 | L15: 0.0035 | M15: -0.01645 | N15: -0.00014 | O15: 1.092 | P15: 0.2212 | Q15: 0.1143 | R15: 0.0371 | S15: -0.0321 | T15: -0.0199 | U15: 0.0102 | V15: 0.0099 | W15: 0.0093 | X15: 0.8905 | Y15: 0.0487 | Z15: 0.0482 | AA15: 0.0301 | AB15: -20587.756 | AC15: -3642.9132 | AD15: -2911.0602 | AE15: -561.2666 | AF15: 0.9924
B16: =B15+1 -> 11 | C16: 0.0331 | D16: 0.0004 | E16: -0.0776 | F16: 0.0031 | G16: -0.001 | H16: -0.0014 | I16: 0.002 | J16: 0.0002 | K16: 0.3653 | L16: 0.0038 | M16: -0.01639 | N16: -0.00014 | O16: 1.2 | P16: 0.2431 | Q16: 0.1256 | R16: 0.0408 | S16: -0.0353 | T16: -0.0218 | U16: 0.0112 | V16: 0.0109 | W16: 0.0102 | X16: 0.9785 | Y16: 0.0535 | Z16: 0.053 | AA16: 0.0331 | AB16: -20521.265 | AC16: -3631.1479 | AD16: -2901.6585 | AE16: -559.4539 | AF16: 0.9908
B17: =B16+1 -> 12 | C17: 0.0361 | D17: 0.0004 | E17: -0.0846 | F17: 0.0033 | G17: -0.0011 | H17: -0.0015 | I17: 0.0022 | J17: 0.0002 | K17: 0.3981 | L17: 0.0042 | M17: -0.01634 | N17: -0.00014 | O17: 1.3075 | P17: 0.2649 | Q17: 0.1369 | R17: 0.0444 | S17: -0.0385 | T17: -0.0238 | U17: 0.0122 | V17: 0.0119 | W17: 0.0111 | X17: 1.0662 | Y17: 0.0583 | Z17: 0.0577 | AA17: 0.036 | AB17: -20448.523 | AC17: -3618.2765 | AD17: -2891.373 | AE17: -557.4708 | AF17: 0.9891
B18: =B17+1 -> 13 | C18: 0.039 | D18: 0.0005 | E18: -0.0915 | F18: 0.0036 | G18: -0.0011 | H18: -0.0017 | I18: 0.0023 | J18: 0.0002 | K18: 0.4307 | L18: 0.0045 | M18: -0.01627 | N18: -0.00014 | O18: 1.4147 | P18: 0.2866 | Q18: 0.1481 | R18: 0.0481 | S18: -0.0416 | T18: -0.0257 | U18: 0.0132 | V18: 0.0128 | W18: 0.012 | X18: 1.1536 | Y18: 0.0631 | Z18: 0.0625 | AA18: 0.039 | AB18: -20369.552 | AC18: -3604.303 | AD18: -2880.2067 | AE18: -555.3179 | AF18: 0.9872
... B365: =B364+1 -> 360 | C365: 0 | D365: 0 | E365: 0 | F365: 0 | G365: 0 | H365: 0 | I365: 0 | J365: 0 | K365: 0 | L365: 0 | M365: -0.0167 | N365: -0.00014 | O365: 0 | P365: 0 | Q365: 0 | R365: 0 | S365: 0 | T365: 0 | U365: 0 | V365: 0 | W365: 0 | X365: 0 | Y365: 0 | Z365: 0 | AA365: 0 | AB365: -20905.355 | AC365: -3699.111 | AD365: -2955.968 | AE365: -569.925 | AF365: 1
B366: =B365+1 -> 361 | C366: T1 | D366: T2 | E366: T3 | F366: T4 | G366: T5 | H366: T6 | I366: T7 | J366: T8 | K366: L1 | L366: L2 | M366: R1 | N366: R2 | O366: M1 | P366: M2 | Q366: M3 | R366: M4 | S366: M5 | T366: M6 | U366: M7 | V366: M8 | W366: M9 | X366: B1 | Y366: B2 | Z366: B3 | AA366: B4 | AB366: r1 | AC366: r2 | AD366: r3 | AE366: r4 | AF366: NQ
